<?xml version="1.0" ?>
<robot name="mi_robot" xmlns:xacro="http://ros.org/wiki/xacro">
  
  <link name="world"/>

  <link name="base_link">
    <visual>
      <geometry>
        <box size="1.0 1.0 0.5"/>
      </geometry>
    </visual>
    <collision>
      <geometry>
        <box size="1.0 1.0 0.5"/>
      </geometry>
    </collision>
  </link>

  <joint name="world_to_base_link" type="fixed">
    <parent link="world"/>
    <child link="base_link"/>
    <origin xyz="0 0 0.25" rpy="0 0 0"/>
  </joint>


  <link name="link_0">
    <visual>
      <origin xyz="0 0 0" rpy="0 0 0"/>
      <geometry>
        <cylinder length="1.1" radius="0.2"/>
      </geometry>
    </visual>
    <collision>
      <geometry>
        <cylinder length="1.1" radius="0.2"/>
      </geometry>
    </collision>
  </link>

  <joint name="base_link_to_link_0" type="revolute">
    <axis xyz="0 0 1"/>
    <limit lower="-3.1416" upper="3.1416" effort="10" velocity="3"/>
    <parent link="base_link"/>
    <child link="link_0"/>
    <origin xyz="0 0 0.8" rpy="0 0 0"/>
  </joint>

  <link name="link_1">
    <visual>
      <origin xyz="0 0 -0.55" rpy="0 0 0"/>
      <geometry>
        <cylinder length="1.1" radius="0.2"/>
      </geometry>
    </visual>
    <collision>
      <geometry>
        <cylinder length="1.1" radius="0.2"/>
      </geometry>
    </collision>
  </link>

  <joint name="link_0_to_link_1" type="revolute">
    <axis xyz="0 1 0"/>
    <limit lower="-3.1416" upper="3.1416" effort="10" velocity="3"/>
    <parent link="link_0"/>
    <child link="link_1"/>
    <origin xyz="0 0 0.55" rpy="0 0 0"/>
  </joint>

</robot>
